[2023-09-11T02:13:48.967+0000] {taskinstance.py:1159} INFO - Dependencies all met for dep_context=non-requeueable deps ti=<TaskInstance: FIBA_dag.create_dataset scheduled__2023-09-09T00:00:00+00:00 [queued]>
[2023-09-11T02:13:48.971+0000] {taskinstance.py:1159} INFO - Dependencies all met for dep_context=requeueable deps ti=<TaskInstance: FIBA_dag.create_dataset scheduled__2023-09-09T00:00:00+00:00 [queued]>
[2023-09-11T02:13:48.972+0000] {taskinstance.py:1361} INFO - Starting attempt 4 of 6
[2023-09-11T02:13:48.979+0000] {taskinstance.py:1382} INFO - Executing <Task(BigQueryCreateEmptyDatasetOperator): create_dataset> on 2023-09-09 00:00:00+00:00
[2023-09-11T02:13:48.984+0000] {standard_task_runner.py:57} INFO - Started process 979 to run task
[2023-09-11T02:13:48.986+0000] {standard_task_runner.py:84} INFO - Running: ['***', 'tasks', 'run', 'FIBA_dag', 'create_dataset', 'scheduled__2023-09-09T00:00:00+00:00', '--job-id', '328', '--raw', '--subdir', 'DAGS_FOLDER/FIBA.py', '--cfg-path', '/tmp/tmp3zd_lpts']
[2023-09-11T02:13:48.989+0000] {standard_task_runner.py:85} INFO - Job 328: Subtask create_dataset
[2023-09-11T02:13:49.019+0000] {task_command.py:415} INFO - Running <TaskInstance: FIBA_dag.create_dataset scheduled__2023-09-09T00:00:00+00:00 [running]> on host 2e8147b3a465
[2023-09-11T02:13:49.061+0000] {taskinstance.py:1660} INFO - Exporting env vars: AIRFLOW_CTX_DAG_OWNER='andy_hsu' AIRFLOW_CTX_DAG_ID='FIBA_dag' AIRFLOW_CTX_TASK_ID='create_dataset' AIRFLOW_CTX_EXECUTION_DATE='2023-09-09T00:00:00+00:00' AIRFLOW_CTX_TRY_NUMBER='4' AIRFLOW_CTX_DAG_RUN_ID='scheduled__2023-09-09T00:00:00+00:00'
[2023-09-11T02:13:49.073+0000] {taskinstance.py:1943} ERROR - Task failed with exception
Traceback (most recent call last):
  File "/home/airflow/.local/lib/python3.8/site-packages/airflow/providers/google/cloud/operators/bigquery.py", line 1993, in execute
    bq_hook = BigQueryHook(
  File "/home/airflow/.local/lib/python3.8/site-packages/airflow/providers/google/cloud/hooks/bigquery.py", line 116, in __init__
    super().__init__(
  File "/home/airflow/.local/lib/python3.8/site-packages/airflow/providers/google/common/hooks/base_google.py", line 237, in __init__
    self.extras: dict = self.get_connection(self.gcp_conn_id).extra_dejson
  File "/home/airflow/.local/lib/python3.8/site-packages/airflow/hooks/base.py", line 72, in get_connection
    conn = Connection.get_connection_from_secrets(conn_id)
  File "/home/airflow/.local/lib/python3.8/site-packages/airflow/models/connection.py", line 477, in get_connection_from_secrets
    raise AirflowNotFoundException(f"The conn_id `{conn_id}` isn't defined")
airflow.exceptions.AirflowNotFoundException: The conn_id `gcp_connection` isn't defined
[2023-09-11T02:13:49.078+0000] {taskinstance.py:1400} INFO - Marking task as UP_FOR_RETRY. dag_id=FIBA_dag, task_id=create_dataset, execution_date=20230909T000000, start_date=20230911T021348, end_date=20230911T021349
[2023-09-11T02:13:49.085+0000] {standard_task_runner.py:104} ERROR - Failed to execute job 328 for task create_dataset (The conn_id `gcp_connection` isn't defined; 979)
[2023-09-11T02:13:49.120+0000] {local_task_job_runner.py:228} INFO - Task exited with return code 1
[2023-09-11T02:13:49.130+0000] {taskinstance.py:2784} INFO - 0 downstream tasks scheduled from follow-on schedule check
