[2023-09-05T05:25:36.532+0000] {taskinstance.py:1159} INFO - Dependencies all met for dep_context=non-requeueable deps ti=<TaskInstance: create_simple_table.create_dataset manual__2023-09-05T05:25:31.402897+00:00 [queued]>
[2023-09-05T05:25:36.537+0000] {taskinstance.py:1159} INFO - Dependencies all met for dep_context=requeueable deps ti=<TaskInstance: create_simple_table.create_dataset manual__2023-09-05T05:25:31.402897+00:00 [queued]>
[2023-09-05T05:25:36.538+0000] {taskinstance.py:1361} INFO - Starting attempt 1 of 1
[2023-09-05T05:25:36.545+0000] {taskinstance.py:1382} INFO - Executing <Task(BigQueryCreateEmptyDatasetOperator): create_dataset> on 2023-09-05 05:25:31.402897+00:00
[2023-09-05T05:25:36.554+0000] {standard_task_runner.py:57} INFO - Started process 1403 to run task
[2023-09-05T05:25:36.556+0000] {standard_task_runner.py:84} INFO - Running: ['***', 'tasks', 'run', 'create_simple_table', 'create_dataset', 'manual__2023-09-05T05:25:31.402897+00:00', '--job-id', '183', '--raw', '--subdir', 'DAGS_FOLDER/dataset.py', '--cfg-path', '/tmp/tmpj90i8zw4']
[2023-09-05T05:25:36.559+0000] {standard_task_runner.py:85} INFO - Job 183: Subtask create_dataset
[2023-09-05T05:25:36.595+0000] {task_command.py:415} INFO - Running <TaskInstance: create_simple_table.create_dataset manual__2023-09-05T05:25:31.402897+00:00 [running]> on host 8ce2b8fabb21
[2023-09-05T05:25:36.640+0000] {taskinstance.py:1660} INFO - Exporting env vars: AIRFLOW_CTX_DAG_EMAIL='' AIRFLOW_CTX_DAG_OWNER='andy.hsu' AIRFLOW_CTX_DAG_ID='create_simple_table' AIRFLOW_CTX_TASK_ID='create_dataset' AIRFLOW_CTX_EXECUTION_DATE='2023-09-05T05:25:31.402897+00:00' AIRFLOW_CTX_TRY_NUMBER='1' AIRFLOW_CTX_DAG_RUN_ID='manual__2023-09-05T05:25:31.402897+00:00'
[2023-09-05T05:25:36.653+0000] {taskinstance.py:1943} ERROR - Task failed with exception
Traceback (most recent call last):
  File "/home/airflow/.local/lib/python3.8/site-packages/airflow/providers/google/cloud/operators/bigquery.py", line 1993, in execute
    bq_hook = BigQueryHook(
  File "/home/airflow/.local/lib/python3.8/site-packages/airflow/providers/google/cloud/hooks/bigquery.py", line 116, in __init__
    super().__init__(
  File "/home/airflow/.local/lib/python3.8/site-packages/airflow/providers/google/common/hooks/base_google.py", line 237, in __init__
    self.extras: dict = self.get_connection(self.gcp_conn_id).extra_dejson
  File "/home/airflow/.local/lib/python3.8/site-packages/airflow/hooks/base.py", line 72, in get_connection
    conn = Connection.get_connection_from_secrets(conn_id)
  File "/home/airflow/.local/lib/python3.8/site-packages/airflow/models/connection.py", line 477, in get_connection_from_secrets
    raise AirflowNotFoundException(f"The conn_id `{conn_id}` isn't defined")
airflow.exceptions.AirflowNotFoundException: The conn_id `google_cloud_default` isn't defined
[2023-09-05T05:25:36.661+0000] {taskinstance.py:1400} INFO - Marking task as FAILED. dag_id=create_simple_table, task_id=create_dataset, execution_date=20230905T052531, start_date=20230905T052536, end_date=20230905T052536
[2023-09-05T05:25:36.668+0000] {standard_task_runner.py:104} ERROR - Failed to execute job 183 for task create_dataset (The conn_id `google_cloud_default` isn't defined; 1403)
[2023-09-05T05:25:36.689+0000] {local_task_job_runner.py:228} INFO - Task exited with return code 1
[2023-09-05T05:25:36.699+0000] {taskinstance.py:2784} INFO - 0 downstream tasks scheduled from follow-on schedule check
