[2023-09-27T03:55:03.141+0000] {taskinstance.py:1159} INFO - Dependencies all met for dep_context=non-requeueable deps ti=<TaskInstance: mlb_parser_ranking.get_rank scheduled__2023-09-26T03:55:00+00:00 [queued]>
[2023-09-27T03:55:03.146+0000] {taskinstance.py:1159} INFO - Dependencies all met for dep_context=requeueable deps ti=<TaskInstance: mlb_parser_ranking.get_rank scheduled__2023-09-26T03:55:00+00:00 [queued]>
[2023-09-27T03:55:03.147+0000] {taskinstance.py:1361} INFO - Starting attempt 1 of 2
[2023-09-27T03:55:03.153+0000] {taskinstance.py:1382} INFO - Executing <Task(PythonOperator): get_rank> on 2023-09-26 03:55:00+00:00
[2023-09-27T03:55:03.157+0000] {standard_task_runner.py:57} INFO - Started process 77809 to run task
[2023-09-27T03:55:03.160+0000] {standard_task_runner.py:84} INFO - Running: ['***', 'tasks', 'run', 'mlb_parser_ranking', 'get_rank', 'scheduled__2023-09-26T03:55:00+00:00', '--job-id', '1570', '--raw', '--subdir', 'DAGS_FOLDER/mlb_parser_ranking.py', '--cfg-path', '/tmp/tmp_11_yqup']
[2023-09-27T03:55:03.162+0000] {standard_task_runner.py:85} INFO - Job 1570: Subtask get_rank
[2023-09-27T03:55:03.192+0000] {task_command.py:415} INFO - Running <TaskInstance: mlb_parser_ranking.get_rank scheduled__2023-09-26T03:55:00+00:00 [running]> on host d98c068596b4
[2023-09-27T03:55:03.242+0000] {taskinstance.py:1660} INFO - Exporting env vars: AIRFLOW_CTX_DAG_OWNER='andy_hsu' AIRFLOW_CTX_DAG_ID='mlb_parser_ranking' AIRFLOW_CTX_TASK_ID='get_rank' AIRFLOW_CTX_EXECUTION_DATE='2023-09-26T03:55:00+00:00' AIRFLOW_CTX_TRY_NUMBER='1' AIRFLOW_CTX_DAG_RUN_ID='scheduled__2023-09-26T03:55:00+00:00'
[2023-09-27T03:55:29.644+0000] {taskinstance.py:1943} ERROR - Task failed with exception
Traceback (most recent call last):
  File "/home/airflow/.local/lib/python3.8/site-packages/urllib3/connectionpool.py", line 714, in urlopen
    httplib_response = self._make_request(
  File "/home/airflow/.local/lib/python3.8/site-packages/urllib3/connectionpool.py", line 403, in _make_request
    self._validate_conn(conn)
  File "/home/airflow/.local/lib/python3.8/site-packages/urllib3/connectionpool.py", line 1053, in _validate_conn
    conn.connect()
  File "/home/airflow/.local/lib/python3.8/site-packages/urllib3/connection.py", line 419, in connect
    self.sock = ssl_wrap_socket(
  File "/home/airflow/.local/lib/python3.8/site-packages/urllib3/util/ssl_.py", line 449, in ssl_wrap_socket
    ssl_sock = _ssl_wrap_socket_impl(
  File "/home/airflow/.local/lib/python3.8/site-packages/urllib3/util/ssl_.py", line 493, in _ssl_wrap_socket_impl
    return ssl_context.wrap_socket(sock, server_hostname=server_hostname)
  File "/usr/local/lib/python3.8/ssl.py", line 500, in wrap_socket
    return self.sslsocket_class._create(
  File "/usr/local/lib/python3.8/ssl.py", line 1040, in _create
    self.do_handshake()
  File "/usr/local/lib/python3.8/ssl.py", line 1309, in do_handshake
    self._sslobj.do_handshake()
ssl.SSLEOFError: EOF occurred in violation of protocol (_ssl.c:1131)

During handling of the above exception, another exception occurred:

Traceback (most recent call last):
  File "/home/airflow/.local/lib/python3.8/site-packages/requests/adapters.py", line 486, in send
    resp = conn.urlopen(
  File "/home/airflow/.local/lib/python3.8/site-packages/urllib3/connectionpool.py", line 798, in urlopen
    retries = retries.increment(
  File "/home/airflow/.local/lib/python3.8/site-packages/urllib3/util/retry.py", line 592, in increment
    raise MaxRetryError(_pool, url, error or ResponseError(cause))
urllib3.exceptions.MaxRetryError: HTTPSConnectionPool(host='statsapi.mlb.com', port=443): Max retries exceeded with url: /api/v1/standings?leagueId=103,104&season=2023&standingsTypes=regularSeason&hydrate=team(division)&fields=records,standingsType,teamRecords,team,name,division,id,nameShort,abbreviation,divisionRank,gamesBack,wildCardRank,wildCardGamesBack,wildCardEliminationNumber,divisionGamesBack,clinched,eliminationNumber,winningPercentage,type,wins,losses (Caused by SSLError(SSLEOFError(8, 'EOF occurred in violation of protocol (_ssl.c:1131)')))

During handling of the above exception, another exception occurred:

Traceback (most recent call last):
  File "/home/airflow/.local/lib/python3.8/site-packages/airflow/operators/python.py", line 192, in execute
    return_value = self.execute_callable()
  File "/home/airflow/.local/lib/python3.8/site-packages/airflow/operators/python.py", line 209, in execute_callable
    return self.python_callable(*self.op_args, **self.op_kwargs)
  File "/opt/airflow/dags/mlb_parser_ranking.py", line 37, in get_rank
    data_source = statsapi.standings_data()
  File "/home/airflow/.local/lib/python3.8/site-packages/statsapi/__init__.py", line 1405, in standings_data
    r = get('standings',params)
  File "/home/airflow/.local/lib/python3.8/site-packages/statsapi/__init__.py", line 1631, in get
    r = requests.get(url)
  File "/home/airflow/.local/lib/python3.8/site-packages/requests/api.py", line 73, in get
    return request("get", url, params=params, **kwargs)
  File "/home/airflow/.local/lib/python3.8/site-packages/requests/api.py", line 59, in request
    return session.request(method=method, url=url, **kwargs)
  File "/home/airflow/.local/lib/python3.8/site-packages/requests/sessions.py", line 589, in request
    resp = self.send(prep, **send_kwargs)
  File "/home/airflow/.local/lib/python3.8/site-packages/requests/sessions.py", line 703, in send
    r = adapter.send(request, **kwargs)
  File "/home/airflow/.local/lib/python3.8/site-packages/requests/adapters.py", line 517, in send
    raise SSLError(e, request=request)
requests.exceptions.SSLError: HTTPSConnectionPool(host='statsapi.mlb.com', port=443): Max retries exceeded with url: /api/v1/standings?leagueId=103,104&season=2023&standingsTypes=regularSeason&hydrate=team(division)&fields=records,standingsType,teamRecords,team,name,division,id,nameShort,abbreviation,divisionRank,gamesBack,wildCardRank,wildCardGamesBack,wildCardEliminationNumber,divisionGamesBack,clinched,eliminationNumber,winningPercentage,type,wins,losses (Caused by SSLError(SSLEOFError(8, 'EOF occurred in violation of protocol (_ssl.c:1131)')))
[2023-09-27T03:55:29.662+0000] {taskinstance.py:1400} INFO - Marking task as UP_FOR_RETRY. dag_id=mlb_parser_ranking, task_id=get_rank, execution_date=20230926T035500, start_date=20230927T035503, end_date=20230927T035529
[2023-09-27T03:55:29.670+0000] {standard_task_runner.py:104} ERROR - Failed to execute job 1570 for task get_rank (HTTPSConnectionPool(host='statsapi.mlb.com', port=443): Max retries exceeded with url: /api/v1/standings?leagueId=103,104&season=2023&standingsTypes=regularSeason&hydrate=team(division)&fields=records,standingsType,teamRecords,team,name,division,id,nameShort,abbreviation,divisionRank,gamesBack,wildCardRank,wildCardGamesBack,wildCardEliminationNumber,divisionGamesBack,clinched,eliminationNumber,winningPercentage,type,wins,losses (Caused by SSLError(SSLEOFError(8, 'EOF occurred in violation of protocol (_ssl.c:1131)'))); 77809)
[2023-09-27T03:55:29.696+0000] {local_task_job_runner.py:228} INFO - Task exited with return code 1
[2023-09-27T03:55:29.705+0000] {taskinstance.py:2784} INFO - 0 downstream tasks scheduled from follow-on schedule check
