[2023-09-16T00:05:18.462+0000] {taskinstance.py:1159} INFO - Dependencies all met for dep_context=non-requeueable deps ti=<TaskInstance: dag_with_postgres_operator_v02.delete_data_from_table scheduled__2023-09-15T00:00:00+00:00 [queued]>
[2023-09-16T00:05:18.477+0000] {taskinstance.py:1159} INFO - Dependencies all met for dep_context=requeueable deps ti=<TaskInstance: dag_with_postgres_operator_v02.delete_data_from_table scheduled__2023-09-15T00:00:00+00:00 [queued]>
[2023-09-16T00:05:18.478+0000] {taskinstance.py:1361} INFO - Starting attempt 2 of 6
[2023-09-16T00:05:18.496+0000] {taskinstance.py:1382} INFO - Executing <Task(PostgresOperator): delete_data_from_table> on 2023-09-15 00:00:00+00:00
[2023-09-16T00:05:18.501+0000] {standard_task_runner.py:57} INFO - Started process 68441 to run task
[2023-09-16T00:05:18.505+0000] {standard_task_runner.py:84} INFO - Running: ['***', 'tasks', 'run', 'dag_with_postgres_operator_v02', 'delete_data_from_table', 'scheduled__2023-09-15T00:00:00+00:00', '--job-id', '876', '--raw', '--subdir', 'DAGS_FOLDER/dag_with_postgre_operator.py', '--cfg-path', '/tmp/tmp0cp275uc']
[2023-09-16T00:05:18.541+0000] {standard_task_runner.py:85} INFO - Job 876: Subtask delete_data_from_table
[2023-09-16T00:05:18.681+0000] {task_command.py:415} INFO - Running <TaskInstance: dag_with_postgres_operator_v02.delete_data_from_table scheduled__2023-09-15T00:00:00+00:00 [running]> on host 2e8147b3a465
[2023-09-16T00:05:18.744+0000] {taskinstance.py:1660} INFO - Exporting env vars: AIRFLOW_CTX_DAG_OWNER='andy_hsu' AIRFLOW_CTX_DAG_ID='dag_with_postgres_operator_v02' AIRFLOW_CTX_TASK_ID='delete_data_from_table' AIRFLOW_CTX_EXECUTION_DATE='2023-09-15T00:00:00+00:00' AIRFLOW_CTX_TRY_NUMBER='2' AIRFLOW_CTX_DAG_RUN_ID='scheduled__2023-09-15T00:00:00+00:00'
[2023-09-16T00:05:18.745+0000] {sql.py:274} INFO - Executing: 
            delete from dag_runs where dt = '2023-09-15' and dag_id values = 'dag_with_postgres_operator_v02'
            
[2023-09-16T00:05:18.752+0000] {base.py:73} INFO - Using connection ID 'postgres_localhost' for task execution.
[2023-09-16T00:05:18.762+0000] {base.py:73} INFO - Using connection ID 'postgres_localhost' for task execution.
[2023-09-16T00:05:18.801+0000] {sql.py:418} INFO - Running statement: 
            delete from dag_runs where dt = '2023-09-15' and dag_id values = 'dag_with_postgres_operator_v02'
            , parameters: None
[2023-09-16T00:05:18.804+0000] {taskinstance.py:1943} ERROR - Task failed with exception
Traceback (most recent call last):
  File "/home/airflow/.local/lib/python3.8/site-packages/airflow/providers/common/sql/operators/sql.py", line 280, in execute
    output = hook.run(
  File "/home/airflow/.local/lib/python3.8/site-packages/airflow/providers/common/sql/hooks/sql.py", line 392, in run
    self._run_command(cur, sql_statement, parameters)
  File "/home/airflow/.local/lib/python3.8/site-packages/airflow/providers/common/sql/hooks/sql.py", line 423, in _run_command
    cur.execute(sql_statement)
psycopg2.errors.SyntaxError: syntax error at or near "values"
LINE 2: ... from dag_runs where dt = '2023-09-15' and dag_id values = '...
                                                             ^

[2023-09-16T00:05:18.813+0000] {taskinstance.py:1400} INFO - Marking task as UP_FOR_RETRY. dag_id=dag_with_postgres_operator_v02, task_id=delete_data_from_table, execution_date=20230915T000000, start_date=20230916T000518, end_date=20230916T000518
[2023-09-16T00:05:18.821+0000] {standard_task_runner.py:104} ERROR - Failed to execute job 876 for task delete_data_from_table (syntax error at or near "values"
LINE 2: ... from dag_runs where dt = '2023-09-15' and dag_id values = '...
                                                             ^
; 68441)
[2023-09-16T00:05:18.859+0000] {local_task_job_runner.py:228} INFO - Task exited with return code 1
[2023-09-16T00:05:18.873+0000] {taskinstance.py:2784} INFO - 0 downstream tasks scheduled from follow-on schedule check
