[2023-09-19T00:28:48.911+0000] {taskinstance.py:1159} INFO - Dependencies all met for dep_context=non-requeueable deps ti=<TaskInstance: dag_with_postgres_operator_v02.delete_data_from_table scheduled__2023-09-18T00:00:00+00:00 [queued]>
[2023-09-19T00:28:48.917+0000] {taskinstance.py:1159} INFO - Dependencies all met for dep_context=requeueable deps ti=<TaskInstance: dag_with_postgres_operator_v02.delete_data_from_table scheduled__2023-09-18T00:00:00+00:00 [queued]>
[2023-09-19T00:28:48.917+0000] {taskinstance.py:1361} INFO - Starting attempt 5 of 6
[2023-09-19T00:28:48.924+0000] {taskinstance.py:1382} INFO - Executing <Task(PostgresOperator): delete_data_from_table> on 2023-09-18 00:00:00+00:00
[2023-09-19T00:28:48.927+0000] {standard_task_runner.py:57} INFO - Started process 41460 to run task
[2023-09-19T00:28:48.930+0000] {standard_task_runner.py:84} INFO - Running: ['***', 'tasks', 'run', 'dag_with_postgres_operator_v02', 'delete_data_from_table', 'scheduled__2023-09-18T00:00:00+00:00', '--job-id', '1232', '--raw', '--subdir', 'DAGS_FOLDER/dag_with_postgre_operator.py', '--cfg-path', '/tmp/tmp44ridqiz']
[2023-09-19T00:28:48.932+0000] {standard_task_runner.py:85} INFO - Job 1232: Subtask delete_data_from_table
[2023-09-19T00:28:48.965+0000] {task_command.py:415} INFO - Running <TaskInstance: dag_with_postgres_operator_v02.delete_data_from_table scheduled__2023-09-18T00:00:00+00:00 [running]> on host 41ed285d8c3c
[2023-09-19T00:28:49.016+0000] {taskinstance.py:1660} INFO - Exporting env vars: AIRFLOW_CTX_DAG_OWNER='andy_hsu' AIRFLOW_CTX_DAG_ID='dag_with_postgres_operator_v02' AIRFLOW_CTX_TASK_ID='delete_data_from_table' AIRFLOW_CTX_EXECUTION_DATE='2023-09-18T00:00:00+00:00' AIRFLOW_CTX_TRY_NUMBER='5' AIRFLOW_CTX_DAG_RUN_ID='scheduled__2023-09-18T00:00:00+00:00'
[2023-09-19T00:28:49.017+0000] {sql.py:274} INFO - Executing: 
            delete from dag_runs where dt = '2023-09-18' and dag_id values = 'dag_with_postgres_operator_v02'
            
[2023-09-19T00:28:49.024+0000] {base.py:73} INFO - Using connection ID 'postgres_localhost' for task execution.
[2023-09-19T00:28:49.030+0000] {base.py:73} INFO - Using connection ID 'postgres_localhost' for task execution.
[2023-09-19T00:28:49.048+0000] {sql.py:418} INFO - Running statement: 
            delete from dag_runs where dt = '2023-09-18' and dag_id values = 'dag_with_postgres_operator_v02'
            , parameters: None
[2023-09-19T00:28:49.052+0000] {taskinstance.py:1943} ERROR - Task failed with exception
Traceback (most recent call last):
  File "/home/airflow/.local/lib/python3.8/site-packages/airflow/providers/common/sql/operators/sql.py", line 280, in execute
    output = hook.run(
  File "/home/airflow/.local/lib/python3.8/site-packages/airflow/providers/common/sql/hooks/sql.py", line 392, in run
    self._run_command(cur, sql_statement, parameters)
  File "/home/airflow/.local/lib/python3.8/site-packages/airflow/providers/common/sql/hooks/sql.py", line 423, in _run_command
    cur.execute(sql_statement)
psycopg2.errors.SyntaxError: syntax error at or near "values"
LINE 2: ... from dag_runs where dt = '2023-09-18' and dag_id values = '...
                                                             ^

[2023-09-19T00:28:49.059+0000] {taskinstance.py:1400} INFO - Marking task as UP_FOR_RETRY. dag_id=dag_with_postgres_operator_v02, task_id=delete_data_from_table, execution_date=20230918T000000, start_date=20230919T002848, end_date=20230919T002849
[2023-09-19T00:28:49.067+0000] {standard_task_runner.py:104} ERROR - Failed to execute job 1232 for task delete_data_from_table (syntax error at or near "values"
LINE 2: ... from dag_runs where dt = '2023-09-18' and dag_id values = '...
                                                             ^
; 41460)
[2023-09-19T00:28:49.103+0000] {local_task_job_runner.py:228} INFO - Task exited with return code 1
[2023-09-19T00:28:49.116+0000] {taskinstance.py:2784} INFO - 0 downstream tasks scheduled from follow-on schedule check
