[2023-09-29T00:23:29.306+0000] {taskinstance.py:1159} INFO - Dependencies all met for dep_context=non-requeueable deps ti=<TaskInstance: dag_with_postgres_operator_v02.delete_data_from_table scheduled__2023-09-28T00:00:00+00:00 [queued]>
[2023-09-29T00:23:29.313+0000] {taskinstance.py:1159} INFO - Dependencies all met for dep_context=requeueable deps ti=<TaskInstance: dag_with_postgres_operator_v02.delete_data_from_table scheduled__2023-09-28T00:00:00+00:00 [queued]>
[2023-09-29T00:23:29.314+0000] {taskinstance.py:1361} INFO - Starting attempt 4 of 6
[2023-09-29T00:23:29.325+0000] {taskinstance.py:1382} INFO - Executing <Task(PostgresOperator): delete_data_from_table> on 2023-09-28 00:00:00+00:00
[2023-09-29T00:23:29.329+0000] {standard_task_runner.py:57} INFO - Started process 55831 to run task
[2023-09-29T00:23:29.332+0000] {standard_task_runner.py:84} INFO - Running: ['***', 'tasks', 'run', 'dag_with_postgres_operator_v02', 'delete_data_from_table', 'scheduled__2023-09-28T00:00:00+00:00', '--job-id', '1622', '--raw', '--subdir', 'DAGS_FOLDER/dag_with_postgre_operator.py', '--cfg-path', '/tmp/tmp81uy8hrs']
[2023-09-29T00:23:29.335+0000] {standard_task_runner.py:85} INFO - Job 1622: Subtask delete_data_from_table
[2023-09-29T00:23:29.367+0000] {task_command.py:415} INFO - Running <TaskInstance: dag_with_postgres_operator_v02.delete_data_from_table scheduled__2023-09-28T00:00:00+00:00 [running]> on host d98c068596b4
[2023-09-29T00:23:29.419+0000] {taskinstance.py:1660} INFO - Exporting env vars: AIRFLOW_CTX_DAG_OWNER='andy_hsu' AIRFLOW_CTX_DAG_ID='dag_with_postgres_operator_v02' AIRFLOW_CTX_TASK_ID='delete_data_from_table' AIRFLOW_CTX_EXECUTION_DATE='2023-09-28T00:00:00+00:00' AIRFLOW_CTX_TRY_NUMBER='4' AIRFLOW_CTX_DAG_RUN_ID='scheduled__2023-09-28T00:00:00+00:00'
[2023-09-29T00:23:29.420+0000] {sql.py:274} INFO - Executing: 
            delete from dag_runs where dt = '2023-09-28' and dag_id values = 'dag_with_postgres_operator_v02'
            
[2023-09-29T00:23:29.425+0000] {base.py:73} INFO - Using connection ID 'postgres_localhost' for task execution.
[2023-09-29T00:23:29.431+0000] {base.py:73} INFO - Using connection ID 'postgres_localhost' for task execution.
[2023-09-29T00:23:29.452+0000] {sql.py:418} INFO - Running statement: 
            delete from dag_runs where dt = '2023-09-28' and dag_id values = 'dag_with_postgres_operator_v02'
            , parameters: None
[2023-09-29T00:23:29.455+0000] {taskinstance.py:1943} ERROR - Task failed with exception
Traceback (most recent call last):
  File "/home/airflow/.local/lib/python3.8/site-packages/airflow/providers/common/sql/operators/sql.py", line 280, in execute
    output = hook.run(
  File "/home/airflow/.local/lib/python3.8/site-packages/airflow/providers/common/sql/hooks/sql.py", line 392, in run
    self._run_command(cur, sql_statement, parameters)
  File "/home/airflow/.local/lib/python3.8/site-packages/airflow/providers/common/sql/hooks/sql.py", line 423, in _run_command
    cur.execute(sql_statement)
psycopg2.errors.SyntaxError: syntax error at or near "values"
LINE 2: ... from dag_runs where dt = '2023-09-28' and dag_id values = '...
                                                             ^

[2023-09-29T00:23:29.461+0000] {taskinstance.py:1400} INFO - Marking task as UP_FOR_RETRY. dag_id=dag_with_postgres_operator_v02, task_id=delete_data_from_table, execution_date=20230928T000000, start_date=20230929T002329, end_date=20230929T002329
[2023-09-29T00:23:29.467+0000] {standard_task_runner.py:104} ERROR - Failed to execute job 1622 for task delete_data_from_table (syntax error at or near "values"
LINE 2: ... from dag_runs where dt = '2023-09-28' and dag_id values = '...
                                                             ^
; 55831)
[2023-09-29T00:23:29.505+0000] {local_task_job_runner.py:228} INFO - Task exited with return code 1
[2023-09-29T00:23:29.518+0000] {taskinstance.py:2784} INFO - 0 downstream tasks scheduled from follow-on schedule check
