[2023-09-12T00:37:45.326+0000] {taskinstance.py:1159} INFO - Dependencies all met for dep_context=non-requeueable deps ti=<TaskInstance: FIBA_dag.create_dataset scheduled__2023-09-11T00:00:00+00:00 [queued]>
[2023-09-12T00:37:45.333+0000] {taskinstance.py:1159} INFO - Dependencies all met for dep_context=requeueable deps ti=<TaskInstance: FIBA_dag.create_dataset scheduled__2023-09-11T00:00:00+00:00 [queued]>
[2023-09-12T00:37:45.334+0000] {taskinstance.py:1361} INFO - Starting attempt 6 of 6
[2023-09-12T00:37:45.342+0000] {taskinstance.py:1382} INFO - Executing <Task(BigQueryCreateEmptyDatasetOperator): create_dataset> on 2023-09-11 00:00:00+00:00
[2023-09-12T00:37:45.348+0000] {standard_task_runner.py:57} INFO - Started process 51836 to run task
[2023-09-12T00:37:45.351+0000] {standard_task_runner.py:84} INFO - Running: ['***', 'tasks', 'run', 'FIBA_dag', 'create_dataset', 'scheduled__2023-09-11T00:00:00+00:00', '--job-id', '462', '--raw', '--subdir', 'DAGS_FOLDER/FIBA.py', '--cfg-path', '/tmp/tmpe2semla9']
[2023-09-12T00:37:45.355+0000] {standard_task_runner.py:85} INFO - Job 462: Subtask create_dataset
[2023-09-12T00:37:45.394+0000] {task_command.py:415} INFO - Running <TaskInstance: FIBA_dag.create_dataset scheduled__2023-09-11T00:00:00+00:00 [running]> on host 2e8147b3a465
[2023-09-12T00:37:45.443+0000] {taskinstance.py:1660} INFO - Exporting env vars: AIRFLOW_CTX_DAG_OWNER='andy_hsu' AIRFLOW_CTX_DAG_ID='FIBA_dag' AIRFLOW_CTX_TASK_ID='create_dataset' AIRFLOW_CTX_EXECUTION_DATE='2023-09-11T00:00:00+00:00' AIRFLOW_CTX_TRY_NUMBER='6' AIRFLOW_CTX_DAG_RUN_ID='scheduled__2023-09-11T00:00:00+00:00'
[2023-09-12T00:37:45.456+0000] {taskinstance.py:1943} ERROR - Task failed with exception
Traceback (most recent call last):
  File "/home/airflow/.local/lib/python3.8/site-packages/airflow/providers/google/cloud/operators/bigquery.py", line 1993, in execute
    bq_hook = BigQueryHook(
  File "/home/airflow/.local/lib/python3.8/site-packages/airflow/providers/google/cloud/hooks/bigquery.py", line 116, in __init__
    super().__init__(
  File "/home/airflow/.local/lib/python3.8/site-packages/airflow/providers/google/common/hooks/base_google.py", line 237, in __init__
    self.extras: dict = self.get_connection(self.gcp_conn_id).extra_dejson
  File "/home/airflow/.local/lib/python3.8/site-packages/airflow/hooks/base.py", line 72, in get_connection
    conn = Connection.get_connection_from_secrets(conn_id)
  File "/home/airflow/.local/lib/python3.8/site-packages/airflow/models/connection.py", line 477, in get_connection_from_secrets
    raise AirflowNotFoundException(f"The conn_id `{conn_id}` isn't defined")
airflow.exceptions.AirflowNotFoundException: The conn_id `gcp_connection` isn't defined
[2023-09-12T00:37:45.466+0000] {taskinstance.py:1400} INFO - Marking task as FAILED. dag_id=FIBA_dag, task_id=create_dataset, execution_date=20230911T000000, start_date=20230912T003745, end_date=20230912T003745
[2023-09-12T00:37:45.475+0000] {standard_task_runner.py:104} ERROR - Failed to execute job 462 for task create_dataset (The conn_id `gcp_connection` isn't defined; 51836)
[2023-09-12T00:37:45.526+0000] {local_task_job_runner.py:228} INFO - Task exited with return code 1
[2023-09-12T00:37:45.538+0000] {taskinstance.py:2784} INFO - 0 downstream tasks scheduled from follow-on schedule check
