[2023-10-13T00:08:19.807+0000] {taskinstance.py:1159} INFO - Dependencies all met for dep_context=non-requeueable deps ti=<TaskInstance: dag_with_postgres_operator_v02.delete_data_from_table scheduled__2023-10-12T00:00:00+00:00 [queued]>
[2023-10-13T00:08:19.815+0000] {taskinstance.py:1159} INFO - Dependencies all met for dep_context=requeueable deps ti=<TaskInstance: dag_with_postgres_operator_v02.delete_data_from_table scheduled__2023-10-12T00:00:00+00:00 [queued]>
[2023-10-13T00:08:19.816+0000] {taskinstance.py:1361} INFO - Starting attempt 2 of 6
[2023-10-13T00:08:19.829+0000] {taskinstance.py:1382} INFO - Executing <Task(PostgresOperator): delete_data_from_table> on 2023-10-12 00:00:00+00:00
[2023-10-13T00:08:19.834+0000] {standard_task_runner.py:57} INFO - Started process 56662 to run task
[2023-10-13T00:08:19.837+0000] {standard_task_runner.py:84} INFO - Running: ['***', 'tasks', 'run', 'dag_with_postgres_operator_v02', 'delete_data_from_table', 'scheduled__2023-10-12T00:00:00+00:00', '--job-id', '1930', '--raw', '--subdir', 'DAGS_FOLDER/dag_with_postgre_operator.py', '--cfg-path', '/tmp/tmpmzybyrs1']
[2023-10-13T00:08:19.840+0000] {standard_task_runner.py:85} INFO - Job 1930: Subtask delete_data_from_table
[2023-10-13T00:08:19.872+0000] {task_command.py:415} INFO - Running <TaskInstance: dag_with_postgres_operator_v02.delete_data_from_table scheduled__2023-10-12T00:00:00+00:00 [running]> on host d98c068596b4
[2023-10-13T00:08:19.925+0000] {taskinstance.py:1660} INFO - Exporting env vars: AIRFLOW_CTX_DAG_OWNER='andy_hsu' AIRFLOW_CTX_DAG_ID='dag_with_postgres_operator_v02' AIRFLOW_CTX_TASK_ID='delete_data_from_table' AIRFLOW_CTX_EXECUTION_DATE='2023-10-12T00:00:00+00:00' AIRFLOW_CTX_TRY_NUMBER='2' AIRFLOW_CTX_DAG_RUN_ID='scheduled__2023-10-12T00:00:00+00:00'
[2023-10-13T00:08:19.926+0000] {sql.py:274} INFO - Executing: 
            delete from dag_runs where dt = '2023-10-12' and dag_id values = 'dag_with_postgres_operator_v02'
            
[2023-10-13T00:08:19.931+0000] {base.py:73} INFO - Using connection ID 'postgres_localhost' for task execution.
[2023-10-13T00:08:19.937+0000] {base.py:73} INFO - Using connection ID 'postgres_localhost' for task execution.
[2023-10-13T00:08:19.950+0000] {sql.py:418} INFO - Running statement: 
            delete from dag_runs where dt = '2023-10-12' and dag_id values = 'dag_with_postgres_operator_v02'
            , parameters: None
[2023-10-13T00:08:19.953+0000] {taskinstance.py:1943} ERROR - Task failed with exception
Traceback (most recent call last):
  File "/home/airflow/.local/lib/python3.8/site-packages/airflow/providers/common/sql/operators/sql.py", line 280, in execute
    output = hook.run(
  File "/home/airflow/.local/lib/python3.8/site-packages/airflow/providers/common/sql/hooks/sql.py", line 392, in run
    self._run_command(cur, sql_statement, parameters)
  File "/home/airflow/.local/lib/python3.8/site-packages/airflow/providers/common/sql/hooks/sql.py", line 423, in _run_command
    cur.execute(sql_statement)
psycopg2.errors.SyntaxError: syntax error at or near "values"
LINE 2: ... from dag_runs where dt = '2023-10-12' and dag_id values = '...
                                                             ^

[2023-10-13T00:08:19.960+0000] {taskinstance.py:1400} INFO - Marking task as UP_FOR_RETRY. dag_id=dag_with_postgres_operator_v02, task_id=delete_data_from_table, execution_date=20231012T000000, start_date=20231013T000819, end_date=20231013T000819
[2023-10-13T00:08:19.967+0000] {standard_task_runner.py:104} ERROR - Failed to execute job 1930 for task delete_data_from_table (syntax error at or near "values"
LINE 2: ... from dag_runs where dt = '2023-10-12' and dag_id values = '...
                                                             ^
; 56662)
[2023-10-13T00:08:20.020+0000] {local_task_job_runner.py:228} INFO - Task exited with return code 1
[2023-10-13T00:08:20.033+0000] {taskinstance.py:2784} INFO - 0 downstream tasks scheduled from follow-on schedule check
