[2023-09-04T17:27:04.220+0000] {taskinstance.py:1159} INFO - Dependencies all met for dep_context=non-requeueable deps ti=<TaskInstance: FIBA_dag.create_dataset manual__2023-09-04T17:27:00.877019+00:00 [queued]>
[2023-09-04T17:27:04.231+0000] {taskinstance.py:1159} INFO - Dependencies all met for dep_context=requeueable deps ti=<TaskInstance: FIBA_dag.create_dataset manual__2023-09-04T17:27:00.877019+00:00 [queued]>
[2023-09-04T17:27:04.233+0000] {taskinstance.py:1361} INFO - Starting attempt 1 of 6
[2023-09-04T17:27:04.244+0000] {taskinstance.py:1382} INFO - Executing <Task(BigQueryCreateEmptyDatasetOperator): create_dataset> on 2023-09-04 17:27:00.877019+00:00
[2023-09-04T17:27:04.250+0000] {standard_task_runner.py:57} INFO - Started process 203 to run task
[2023-09-04T17:27:04.254+0000] {standard_task_runner.py:84} INFO - Running: ['***', 'tasks', 'run', 'FIBA_dag', 'create_dataset', 'manual__2023-09-04T17:27:00.877019+00:00', '--job-id', '143', '--raw', '--subdir', 'DAGS_FOLDER/FIBA.py', '--cfg-path', '/tmp/tmp4_adffa7']
[2023-09-04T17:27:04.258+0000] {standard_task_runner.py:85} INFO - Job 143: Subtask create_dataset
[2023-09-04T17:27:04.331+0000] {task_command.py:415} INFO - Running <TaskInstance: FIBA_dag.create_dataset manual__2023-09-04T17:27:00.877019+00:00 [running]> on host 14cd347b1f24
[2023-09-04T17:27:04.411+0000] {taskinstance.py:1660} INFO - Exporting env vars: AIRFLOW_CTX_DAG_OWNER='andy_hsu' AIRFLOW_CTX_DAG_ID='FIBA_dag' AIRFLOW_CTX_TASK_ID='create_dataset' AIRFLOW_CTX_EXECUTION_DATE='2023-09-04T17:27:00.877019+00:00' AIRFLOW_CTX_TRY_NUMBER='1' AIRFLOW_CTX_DAG_RUN_ID='manual__2023-09-04T17:27:00.877019+00:00'
[2023-09-04T17:27:04.424+0000] {taskinstance.py:1943} ERROR - Task failed with exception
Traceback (most recent call last):
  File "/home/airflow/.local/lib/python3.8/site-packages/airflow/providers/google/cloud/operators/bigquery.py", line 1993, in execute
    bq_hook = BigQueryHook(
  File "/home/airflow/.local/lib/python3.8/site-packages/airflow/providers/google/cloud/hooks/bigquery.py", line 116, in __init__
    super().__init__(
  File "/home/airflow/.local/lib/python3.8/site-packages/airflow/providers/google/common/hooks/base_google.py", line 237, in __init__
    self.extras: dict = self.get_connection(self.gcp_conn_id).extra_dejson
  File "/home/airflow/.local/lib/python3.8/site-packages/airflow/hooks/base.py", line 72, in get_connection
    conn = Connection.get_connection_from_secrets(conn_id)
  File "/home/airflow/.local/lib/python3.8/site-packages/airflow/models/connection.py", line 477, in get_connection_from_secrets
    raise AirflowNotFoundException(f"The conn_id `{conn_id}` isn't defined")
airflow.exceptions.AirflowNotFoundException: The conn_id `google_cloud_default` isn't defined
[2023-09-04T17:27:04.432+0000] {taskinstance.py:1400} INFO - Marking task as UP_FOR_RETRY. dag_id=FIBA_dag, task_id=create_dataset, execution_date=20230904T172700, start_date=20230904T172704, end_date=20230904T172704
[2023-09-04T17:27:04.440+0000] {standard_task_runner.py:104} ERROR - Failed to execute job 143 for task create_dataset (The conn_id `google_cloud_default` isn't defined; 203)
[2023-09-04T17:27:04.471+0000] {local_task_job_runner.py:228} INFO - Task exited with return code 1
[2023-09-04T17:27:04.483+0000] {taskinstance.py:2784} INFO - 0 downstream tasks scheduled from follow-on schedule check
