[2023-09-01T02:52:56.165+0000] {taskinstance.py:1159} INFO - Dependencies all met for dep_context=non-requeueable deps ti=<TaskInstance: our_dag_with_python_oerator_v04.greet manual__2023-09-01T02:52:54.058137+00:00 [queued]>
[2023-09-01T02:52:56.172+0000] {taskinstance.py:1159} INFO - Dependencies all met for dep_context=requeueable deps ti=<TaskInstance: our_dag_with_python_oerator_v04.greet manual__2023-09-01T02:52:54.058137+00:00 [queued]>
[2023-09-01T02:52:56.173+0000] {taskinstance.py:1361} INFO - Starting attempt 1 of 6
[2023-09-01T02:52:56.182+0000] {taskinstance.py:1382} INFO - Executing <Task(PythonOperator): greet> on 2023-09-01 02:52:54.058137+00:00
[2023-09-01T02:52:56.186+0000] {standard_task_runner.py:57} INFO - Started process 4321 to run task
[2023-09-01T02:52:56.188+0000] {standard_task_runner.py:84} INFO - Running: ['***', 'tasks', 'run', 'our_dag_with_python_oerator_v04', 'greet', 'manual__2023-09-01T02:52:54.058137+00:00', '--job-id', '10', '--raw', '--subdir', 'DAGS_FOLDER/create_dag_with_python_operator.py', '--cfg-path', '/tmp/tmpoenp59kb']
[2023-09-01T02:52:56.191+0000] {standard_task_runner.py:85} INFO - Job 10: Subtask greet
[2023-09-01T02:52:56.225+0000] {task_command.py:415} INFO - Running <TaskInstance: our_dag_with_python_oerator_v04.greet manual__2023-09-01T02:52:54.058137+00:00 [running]> on host ad6c67079ac6
[2023-09-01T02:52:56.269+0000] {taskinstance.py:1660} INFO - Exporting env vars: AIRFLOW_CTX_DAG_OWNER='andy_hsu' AIRFLOW_CTX_DAG_ID='our_dag_with_python_oerator_v04' AIRFLOW_CTX_TASK_ID='greet' AIRFLOW_CTX_EXECUTION_DATE='2023-09-01T02:52:54.058137+00:00' AIRFLOW_CTX_TRY_NUMBER='1' AIRFLOW_CTX_DAG_RUN_ID='manual__2023-09-01T02:52:54.058137+00:00'
[2023-09-01T02:52:56.272+0000] {taskinstance.py:1943} ERROR - Task failed with exception
Traceback (most recent call last):
  File "/home/airflow/.local/lib/python3.8/site-packages/airflow/operators/python.py", line 192, in execute
    return_value = self.execute_callable()
  File "/home/airflow/.local/lib/python3.8/site-packages/airflow/operators/python.py", line 209, in execute_callable
    return self.python_callable(*self.op_args, **self.op_kwargs)
  File "/opt/airflow/dags/create_dag_with_python_operator.py", line 12, in greet
    name = ti.xcoms_pull(task_ids = 'get_name')
AttributeError: 'TaskInstance' object has no attribute 'xcoms_pull'
[2023-09-01T02:52:56.280+0000] {taskinstance.py:1400} INFO - Marking task as UP_FOR_RETRY. dag_id=our_dag_with_python_oerator_v04, task_id=greet, execution_date=20230901T025254, start_date=20230901T025256, end_date=20230901T025256
[2023-09-01T02:52:56.287+0000] {standard_task_runner.py:104} ERROR - Failed to execute job 10 for task greet ('TaskInstance' object has no attribute 'xcoms_pull'; 4321)
[2023-09-01T02:52:56.321+0000] {local_task_job_runner.py:228} INFO - Task exited with return code 1
[2023-09-01T02:52:56.331+0000] {taskinstance.py:2784} INFO - 0 downstream tasks scheduled from follow-on schedule check
