[2023-09-01T08:44:27.674+0000] {taskinstance.py:1159} INFO - Dependencies all met for dep_context=non-requeueable deps ti=<TaskInstance: our_dag_with_python_oerator_v05.greet manual__2023-09-01T08:44:25.435850+00:00 [queued]>
[2023-09-01T08:44:27.680+0000] {taskinstance.py:1159} INFO - Dependencies all met for dep_context=requeueable deps ti=<TaskInstance: our_dag_with_python_oerator_v05.greet manual__2023-09-01T08:44:25.435850+00:00 [queued]>
[2023-09-01T08:44:27.681+0000] {taskinstance.py:1361} INFO - Starting attempt 1 of 6
[2023-09-01T08:44:27.687+0000] {taskinstance.py:1382} INFO - Executing <Task(PythonOperator): greet> on 2023-09-01 08:44:25.435850+00:00
[2023-09-01T08:44:27.691+0000] {standard_task_runner.py:57} INFO - Started process 11262 to run task
[2023-09-01T08:44:27.693+0000] {standard_task_runner.py:84} INFO - Running: ['***', 'tasks', 'run', 'our_dag_with_python_oerator_v05', 'greet', 'manual__2023-09-01T08:44:25.435850+00:00', '--job-id', '31', '--raw', '--subdir', 'DAGS_FOLDER/create_dag_with_python_operator.py', '--cfg-path', '/tmp/tmp0qyhy_4a']
[2023-09-01T08:44:27.695+0000] {standard_task_runner.py:85} INFO - Job 31: Subtask greet
[2023-09-01T08:44:27.727+0000] {task_command.py:415} INFO - Running <TaskInstance: our_dag_with_python_oerator_v05.greet manual__2023-09-01T08:44:25.435850+00:00 [running]> on host ad6c67079ac6
[2023-09-01T08:44:27.768+0000] {taskinstance.py:1660} INFO - Exporting env vars: AIRFLOW_CTX_DAG_OWNER='andy_hsu' AIRFLOW_CTX_DAG_ID='our_dag_with_python_oerator_v05' AIRFLOW_CTX_TASK_ID='greet' AIRFLOW_CTX_EXECUTION_DATE='2023-09-01T08:44:25.435850+00:00' AIRFLOW_CTX_TRY_NUMBER='1' AIRFLOW_CTX_DAG_RUN_ID='manual__2023-09-01T08:44:25.435850+00:00'
[2023-09-01T08:44:27.770+0000] {taskinstance.py:1943} ERROR - Task failed with exception
Traceback (most recent call last):
  File "/home/airflow/.local/lib/python3.8/site-packages/airflow/operators/python.py", line 189, in execute
    context_merge(context, self.op_kwargs, templates_dict=self.templates_dict)
  File "/home/airflow/.local/lib/python3.8/site-packages/airflow/utils/context.py", line 260, in context_merge
    context.update(*args, **kwargs)
  File "/usr/local/lib/python3.8/_collections_abc.py", line 837, in update
    for key, value in other:
ValueError: too many values to unpack (expected 2)
[2023-09-01T08:44:27.776+0000] {taskinstance.py:1400} INFO - Marking task as UP_FOR_RETRY. dag_id=our_dag_with_python_oerator_v05, task_id=greet, execution_date=20230901T084425, start_date=20230901T084427, end_date=20230901T084427
[2023-09-01T08:44:27.783+0000] {standard_task_runner.py:104} ERROR - Failed to execute job 31 for task greet (too many values to unpack (expected 2); 11262)
[2023-09-01T08:44:27.826+0000] {local_task_job_runner.py:228} INFO - Task exited with return code 1
[2023-09-01T08:44:27.836+0000] {taskinstance.py:2784} INFO - 0 downstream tasks scheduled from follow-on schedule check
