[2023-09-01T08:41:26.967+0000] {taskinstance.py:1159} INFO - Dependencies all met for dep_context=non-requeueable deps ti=<TaskInstance: our_dag_with_python_oerator_v05.greet manual__2023-09-01T08:41:25.280237+00:00 [queued]>
[2023-09-01T08:41:26.973+0000] {taskinstance.py:1159} INFO - Dependencies all met for dep_context=requeueable deps ti=<TaskInstance: our_dag_with_python_oerator_v05.greet manual__2023-09-01T08:41:25.280237+00:00 [queued]>
[2023-09-01T08:41:26.974+0000] {taskinstance.py:1361} INFO - Starting attempt 1 of 6
[2023-09-01T08:41:26.982+0000] {taskinstance.py:1382} INFO - Executing <Task(PythonOperator): greet> on 2023-09-01 08:41:25.280237+00:00
[2023-09-01T08:41:26.986+0000] {standard_task_runner.py:57} INFO - Started process 11144 to run task
[2023-09-01T08:41:26.988+0000] {standard_task_runner.py:84} INFO - Running: ['***', 'tasks', 'run', 'our_dag_with_python_oerator_v05', 'greet', 'manual__2023-09-01T08:41:25.280237+00:00', '--job-id', '27', '--raw', '--subdir', 'DAGS_FOLDER/create_dag_with_python_operator.py', '--cfg-path', '/tmp/tmpzrk_pis6']
[2023-09-01T08:41:26.991+0000] {standard_task_runner.py:85} INFO - Job 27: Subtask greet
[2023-09-01T08:41:27.024+0000] {task_command.py:415} INFO - Running <TaskInstance: our_dag_with_python_oerator_v05.greet manual__2023-09-01T08:41:25.280237+00:00 [running]> on host ad6c67079ac6
[2023-09-01T08:41:27.076+0000] {taskinstance.py:1660} INFO - Exporting env vars: AIRFLOW_CTX_DAG_OWNER='andy_hsu' AIRFLOW_CTX_DAG_ID='our_dag_with_python_oerator_v05' AIRFLOW_CTX_TASK_ID='greet' AIRFLOW_CTX_EXECUTION_DATE='2023-09-01T08:41:25.280237+00:00' AIRFLOW_CTX_TRY_NUMBER='1' AIRFLOW_CTX_DAG_RUN_ID='manual__2023-09-01T08:41:25.280237+00:00'
[2023-09-01T08:41:27.080+0000] {taskinstance.py:1943} ERROR - Task failed with exception
Traceback (most recent call last):
  File "/home/airflow/.local/lib/python3.8/site-packages/airflow/operators/python.py", line 189, in execute
    context_merge(context, self.op_kwargs, templates_dict=self.templates_dict)
  File "/home/airflow/.local/lib/python3.8/site-packages/airflow/utils/context.py", line 260, in context_merge
    context.update(*args, **kwargs)
  File "/usr/local/lib/python3.8/_collections_abc.py", line 837, in update
    for key, value in other:
ValueError: too many values to unpack (expected 2)
[2023-09-01T08:41:27.090+0000] {taskinstance.py:1400} INFO - Marking task as UP_FOR_RETRY. dag_id=our_dag_with_python_oerator_v05, task_id=greet, execution_date=20230901T084125, start_date=20230901T084126, end_date=20230901T084127
[2023-09-01T08:41:27.103+0000] {standard_task_runner.py:104} ERROR - Failed to execute job 27 for task greet (too many values to unpack (expected 2); 11144)
[2023-09-01T08:41:27.128+0000] {local_task_job_runner.py:228} INFO - Task exited with return code 1
[2023-09-01T08:41:27.138+0000] {taskinstance.py:2784} INFO - 0 downstream tasks scheduled from follow-on schedule check
