[2023-09-01T08:46:31.820+0000] {taskinstance.py:1159} INFO - Dependencies all met for dep_context=non-requeueable deps ti=<TaskInstance: our_dag_with_python_oerator_v05.greet manual__2023-09-01T08:46:29.829996+00:00 [queued]>
[2023-09-01T08:46:31.825+0000] {taskinstance.py:1159} INFO - Dependencies all met for dep_context=requeueable deps ti=<TaskInstance: our_dag_with_python_oerator_v05.greet manual__2023-09-01T08:46:29.829996+00:00 [queued]>
[2023-09-01T08:46:31.826+0000] {taskinstance.py:1361} INFO - Starting attempt 1 of 6
[2023-09-01T08:46:31.833+0000] {taskinstance.py:1382} INFO - Executing <Task(PythonOperator): greet> on 2023-09-01 08:46:29.829996+00:00
[2023-09-01T08:46:31.837+0000] {standard_task_runner.py:57} INFO - Started process 11339 to run task
[2023-09-01T08:46:31.839+0000] {standard_task_runner.py:84} INFO - Running: ['***', 'tasks', 'run', 'our_dag_with_python_oerator_v05', 'greet', 'manual__2023-09-01T08:46:29.829996+00:00', '--job-id', '34', '--raw', '--subdir', 'DAGS_FOLDER/create_dag_with_python_operator.py', '--cfg-path', '/tmp/tmp1n279wex']
[2023-09-01T08:46:31.842+0000] {standard_task_runner.py:85} INFO - Job 34: Subtask greet
[2023-09-01T08:46:31.870+0000] {task_command.py:415} INFO - Running <TaskInstance: our_dag_with_python_oerator_v05.greet manual__2023-09-01T08:46:29.829996+00:00 [running]> on host ad6c67079ac6
[2023-09-01T08:46:31.908+0000] {taskinstance.py:1660} INFO - Exporting env vars: AIRFLOW_CTX_DAG_OWNER='andy_hsu' AIRFLOW_CTX_DAG_ID='our_dag_with_python_oerator_v05' AIRFLOW_CTX_TASK_ID='greet' AIRFLOW_CTX_EXECUTION_DATE='2023-09-01T08:46:29.829996+00:00' AIRFLOW_CTX_TRY_NUMBER='1' AIRFLOW_CTX_DAG_RUN_ID='manual__2023-09-01T08:46:29.829996+00:00'
[2023-09-01T08:46:31.910+0000] {taskinstance.py:1943} ERROR - Task failed with exception
Traceback (most recent call last):
  File "/home/airflow/.local/lib/python3.8/site-packages/airflow/operators/python.py", line 192, in execute
    return_value = self.execute_callable()
  File "/home/airflow/.local/lib/python3.8/site-packages/airflow/operators/python.py", line 209, in execute_callable
    return self.python_callable(*self.op_args, **self.op_kwargs)
  File "/opt/airflow/dags/create_dag_with_python_operator.py", line 12, in greet
    first_name = ti.xcom_pull(task_ids = 'get_name', keu = 'first_name')
  File "/home/airflow/.local/lib/python3.8/site-packages/airflow/utils/session.py", line 77, in wrapper
    return func(*args, session=session, **kwargs)
TypeError: xcom_pull() got an unexpected keyword argument 'keu'
[2023-09-01T08:46:31.917+0000] {taskinstance.py:1400} INFO - Marking task as UP_FOR_RETRY. dag_id=our_dag_with_python_oerator_v05, task_id=greet, execution_date=20230901T084629, start_date=20230901T084631, end_date=20230901T084631
[2023-09-01T08:46:31.923+0000] {standard_task_runner.py:104} ERROR - Failed to execute job 34 for task greet (xcom_pull() got an unexpected keyword argument 'keu'; 11339)
[2023-09-01T08:46:31.931+0000] {local_task_job_runner.py:228} INFO - Task exited with return code 1
[2023-09-01T08:46:31.941+0000] {taskinstance.py:2784} INFO - 0 downstream tasks scheduled from follow-on schedule check
